<robot
  name="ROBOTLIGHT">
  <link
    name="base_link">
    <inertial>
      <origin
        xyz="0.00020918 -0.10929 -0.00041315"
        rpy="0 0 0" />
      <mass
        value="1.6694" />
      <inertia
        ixx="0.0066414"
        ixy="-2.706E-05"
        ixz="-1.2574E-05"
        iyy="0.0043803"
        iyz="5.2791E-05"
        izz="0.0066653" />
    </inertial>
    <visual>
      <origin
        xyz="0 0 0"
        rpy="0 0 0" />
      <geometry>
        <mesh
          filename="package://ROBOTLIGHT/meshes/base_link.STL" />
      </geometry>
      <material
        name="">
        <color
          rgba="1 1 1 1" />
      </material>
    </visual>
    <collision>
      <origin
        xyz="0 0 0"
        rpy="0 0 0" />
      <geometry>
        <mesh
          filename="package://ROBOTLIGHT/meshes/base_link.STL" />
      </geometry>
    </collision>
  </link>
  <link
    name="Link1">
    <inertial>
      <origin
        xyz="0.015731 -5.0475E-07 0.10307"
        rpy="0 0 0" />
      <mass
        value="1.6792" />
      <inertia
        ixx="0.0044576"
        ixy="-5.4141E-08"
        ixz="-0.00015338"
        iyy="0.0051838"
        iyz="-2.7052E-07"
        izz="0.0046589" />
    </inertial>
    <visual>
      <origin
        xyz="0 0 0"
        rpy="0 0 0" />
      <geometry>
        <mesh
          filename="package://ROBOTLIGHT/meshes/Link1.STL" />
      </geometry>
      <material
        name="">
        <color
          rgba="1 1 1 1" />
      </material>
    </visual>
    <collision>
      <origin
        xyz="0 0 0"
        rpy="0 0 0" />
      <geometry>
        <mesh
          filename="package://ROBOTLIGHT/meshes/Link1.STL" />
      </geometry>
    </collision>
  </link>
  <joint
    name="J1"
    type="revolute">
    <origin
      xyz="0 -0.207 0"
      rpy="1.5708 -1.5708 0" />
    <parent
      link="base_link" />
    <child
      link="Link1" />
    <axis
      xyz="0 0 1" />
    <limit
      lower="-3.14"
      upper="3.14"
      effort="0"
      velocity="0" />
  </joint>
  <link
    name="Link2">
    <inertial>
      <origin
        xyz="-0.14529 8.2711E-06 0.0004616"
        rpy="0 0 0" />
      <mass
        value="2.2382" />
      <inertia
        ixx="0.0060191"
        ixy="-6.5444E-07"
        ixz="0.0005287"
        iyy="0.016837"
        iyz="7.8068E-07"
        izz="0.014936" />
    </inertial>
    <visual>
      <origin
        xyz="0 0 0"
        rpy="0 0 0" />
      <geometry>
        <mesh
          filename="package://ROBOTLIGHT/meshes/Link2.STL" />
      </geometry>
      <material
        name="">
        <color
          rgba="1 1 1 1" />
      </material>
    </visual>
    <collision>
      <origin
        xyz="0 0 0"
        rpy="0 0 0" />
      <geometry>
        <mesh
          filename="package://ROBOTLIGHT/meshes/Link2.STL" />
      </geometry>
    </collision>
  </link>
  <joint
    name="J2"
    type="revolute">
    <origin
      xyz="0.002 0 0.108"
      rpy="3.1416 1.5708 0" />
    <parent
      link="Link1" />
    <child
      link="Link2" />
    <axis
      xyz="0 0 1" />
    <limit
      lower="-1.57"
      upper="1.57"
      effort="0"
      velocity="0" />
  </joint>
  <link
    name="Link3">
    <inertial>
      <origin
        xyz="0.0039832 -8.125E-06 0.095598"
        rpy="0 0 0" />
      <mass
        value="1.3965" />
      <inertia
        ixx="0.0026599"
        ixy="3.599E-07"
        ixz="-2.7883E-05"
        iyy="0.0035048"
        iyz="-8.7837E-07"
        izz="0.0032081" />
    </inertial>
    <visual>
      <origin
        xyz="0 0 0"
        rpy="0 0 0" />
      <geometry>
        <mesh
          filename="package://ROBOTLIGHT/meshes/Link3.STL" />
      </geometry>
      <material
        name="">
        <color
          rgba="1 1 1 1" />
      </material>
    </visual>
    <collision>
      <origin
        xyz="0 0 0"
        rpy="0 0 0" />
      <geometry>
        <mesh
          filename="package://ROBOTLIGHT/meshes/Link3.STL" />
      </geometry>
    </collision>
  </link>
  <joint
    name="J3"
    type="revolute">
    <origin
      xyz="-0.26644 0 0.002"
      rpy="3.1416 1.5708 0" />
    <parent
      link="Link2" />
    <child
      link="Link3" />
    <axis
      xyz="0 0 1" />
    <limit
      lower="-3.14"
      upper="3.14"
      effort="0"
      velocity="0" />
  </joint>
  <link
    name="Link4">
    <inertial>
      <origin
        xyz="-0.11517 8.9192E-06 -0.00030972"
        rpy="0 0 0" />
      <mass
        value="1.1436" />
      <inertia
        ixx="0.0023078"
        ixy="-3.8141E-07"
        ixz="0.00028079"
        iyy="0.0070586"
        iyz="2.8435E-07"
        izz="0.0060872" />
    </inertial>
    <visual>
      <origin
        xyz="0 0 0"
        rpy="0 0 0" />
      <geometry>
        <mesh
          filename="package://ROBOTLIGHT/meshes/Link4.STL" />
      </geometry>
      <material
        name="">
        <color
          rgba="1 1 1 1" />
      </material>
    </visual>
    <collision>
      <origin
        xyz="0 0 0"
        rpy="0 0 0" />
      <geometry>
        <mesh
          filename="package://ROBOTLIGHT/meshes/Link4.STL" />
      </geometry>
    </collision>
  </link>
  <joint
    name="J4"
    type="revolute">
    <origin
      xyz="0.00175 0 0.099"
      rpy="3.1416 1.5708 0" />
    <parent
      link="Link3" />
    <child
      link="Link4" />
    <axis
      xyz="0 0 1" />
    <limit
      lower="-1.57"
      upper="1.57"
      effort="0"
      velocity="0" />
  </joint>
  <link
    name="Link5">
    <inertial>
      <origin
        xyz="0.0011836 5.0938E-06 0.085842"
        rpy="0 0 0" />
      <mass
        value="0.74464" />
      <inertia
        ixx="0.0010737"
        ixy="1.4745E-07"
        ixz="-6.3113E-06"
        iyy="0.0014181"
        iyz="2.914E-07"
        izz="0.0011378" />
    </inertial>
    <visual>
      <origin
        xyz="0 0 0"
        rpy="0 0 0" />
      <geometry>
        <mesh
          filename="package://ROBOTLIGHT/meshes/Link5.STL" />
      </geometry>
      <material
        name="">
        <color
          rgba="1 1 1 1" />
      </material>
    </visual>
    <collision>
      <origin
        xyz="0 0 0"
        rpy="0 0 0" />
      <geometry>
        <mesh
          filename="package://ROBOTLIGHT/meshes/Link5.STL" />
      </geometry>
    </collision>
  </link>
  <joint
    name="J5"
    type="revolute">
    <origin
      xyz="-0.2205 0 0.00175"
      rpy="3.1416 1.5708 0" />
    <parent
      link="Link4" />
    <child
      link="Link5" />
    <axis
      xyz="0 0 1" />
    <limit
      lower="-3.14"
      upper="3.14"
      effort="0"
      velocity="0" />
  </joint>
  <link
    name="Link6">
    <inertial>
      <origin
        xyz="-0.11294 1.5608E-05 -0.0012035"
        rpy="0 0 0" />
      <mass
        value="1.0309" />
      <inertia
        ixx="0.0014412"
        ixy="-8.2303E-07"
        ixz="0.00012006"
        iyy="0.0044929"
        iyz="1.968E-07"
        izz="0.004086" />
    </inertial>
    <visual>
      <origin
        xyz="0 0 0"
        rpy="0 0 0" />
      <geometry>
        <mesh
          filename="package://ROBOTLIGHT/meshes/Link6.STL" />
      </geometry>
      <material
        name="">
        <color
          rgba="1 1 1 1" />
      </material>
    </visual>
    <collision>
      <origin
        xyz="0 0 0"
        rpy="0 0 0" />
      <geometry>
        <mesh
          filename="package://ROBOTLIGHT/meshes/Link6.STL" />
      </geometry>
    </collision>
  </link>
  <joint
    name="J6"
    type="revolute">
    <origin
      xyz="-0.00025 0 0.093"
      rpy="3.1416 1.5708 0" />
    <parent
      link="Link5" />
    <child
      link="Link6" />
    <axis
      xyz="0 0 1" />
    <limit
      lower="-1.57"
      upper="1.57"
      effort="0"
      velocity="0" />
  </joint>
  <link
    name="Link7">
    <inertial>
      <origin
        xyz="1.8237E-16 -1.5455E-17 0.0040437"
        rpy="0 0 0" />
      <mass
        value="0.040569" />
      <inertia
        ixx="1.468E-05"
        ixy="-9.5291E-21"
        ixz="3.4593E-21"
        iyy="1.468E-05"
        iyz="-1.0279E-21"
        izz="2.8966E-05" />
    </inertial>
    <visual>
      <origin
        xyz="0 0 0"
        rpy="0 0 0" />
      <geometry>
        <mesh
          filename="package://ROBOTLIGHT/meshes/Link7.STL" />
      </geometry>
      <material
        name="">
        <color
          rgba="0.50196 1 1 1" />
      </material>
    </visual>
    <collision>
      <origin
        xyz="0 0 0"
        rpy="0 0 0" />
      <geometry>
        <mesh
          filename="package://ROBOTLIGHT/meshes/Link7.STL" />
      </geometry>
    </collision>
  </link>
  <joint
    name="J7"
    type="revolute">
    <origin
      xyz="-0.209 0 -0.00025"
      rpy="-1.5708 -0.039586 -1.5708" />
    <parent
      link="Link6" />
    <child
      link="Link7" />
    <axis
      xyz="0 0 1" />
    <limit
      lower="-3.14"
      upper="3.14"
      effort="0"
      velocity="0" />
  </joint>
</robot>